<?xml version="1.0"?>
<robot name="balance_bot">
  <link name="base_link">
    <visual>
      <geometry>
        <box size="0.3 0.15 0.6"/>
      </geometry>
      <origin xyz="0 0 0" rpy="0 0 1.5708"/>
    </visual>
    <collision>
      <geometry>
        <box size="0.3 0.15 0.6"/>
      </geometry>
      <origin xyz="0 0 0" rpy="0 0 1.5708"/>
    </collision>
    <inertial>
      <mass value="1.0"/>
      <inertia ixx="0.01" iyy="0.01" izz="0.01" ixy="0" ixz="0" iyz="0"/>
    </inertial>
  </link>

  <link name="left_wheel">
    <visual>
      <geometry>
        <cylinder radius="0.15" length="0.06"/>
      </geometry>
      <origin xyz="0 0 0" rpy="1.5708 0 0"/>
    </visual>
    <collision>
      <geometry>
        <cylinder radius="0.15" length="0.06"/>
      </geometry>
      <origin xyz="0 0 0" rpy="1.5708 0 0"/>
    </collision>
    <inertial>
      <mass value="0.2"/>
      <inertia ixx="0.001" iyy="0.001" izz="0.001" ixy="0" ixz="0" iyz="0"/>
    </inertial>
  </link>

  <link name="right_wheel">
    <visual>
      <geometry>
        <cylinder radius="0.15" length="0.06"/>
      </geometry>
      <origin xyz="0 0 0" rpy="1.5708 0 0"/>
    </visual>
    <collision>
      <geometry>
        <cylinder radius="0.15" length="0.06"/>
      </geometry>
      <origin xyz="0 0 0" rpy="1.5708 0 0"/>
    </collision>
    <inertial>
      <mass value="0.2"/>
      <inertia ixx="0.001" iyy="0.001" izz="0.001" ixy="0" ixz="0" iyz="0"/>
    </inertial>
  </link>

  <joint name="left_wheel_joint" type="continuous">
    <parent link="base_link"/>
    <child link="left_wheel"/>
    <origin xyz="0 0.225 -0.3" rpy="0 0 0"/>
    <axis xyz="0 1 0"/>
    <dynamics damping="0.1"/>
  </joint>

  <joint name="right_wheel_joint" type="continuous">
    <parent link="base_link"/>
    <child link="right_wheel"/>
    <origin xyz="0 -0.225 -0.3" rpy="0 0 0"/>
    <axis xyz="0 1 0"/>
    <dynamics damping="0.1"/>
  </joint>

  <link name="imu_link">
    <visual>
      <geometry>
        <box size="0.05 0.05 0.05"/>
      </geometry>
      <origin xyz="0 0 0" rpy="0 0 0"/>
    </visual>
    <collision>
      <geometry>
        <box size="0.05 0.05 0.05"/>
      </geometry>
      <origin xyz="0 0 0" rpy="0 0 0"/>
    </collision>
    <inertial>
      <mass value="0.01"/>
      <inertia ixx="0.0001" ixy="0.0" ixz="0.0" iyy="0.0001" iyz="0.0" izz="0.0001"/>
    </inertial>
  </link>

  <joint name="imu_joint" type="fixed">
    <parent link="base_link"/>
    <child link="imu_link"/>
    <origin xyz="0 0 -0.3" rpy="0 0 0"/>
  </joint>

</robot>
