<?xml version="1.0"?>
<robot name="balance_bot">

  <material name="body">
    <color rgba="0.5 0.5 0.5 1"/>
  </material>

  <material name="wheel">
    <color rgba="0.2 0.2 0.2 1"/>
  </material>

  <link name="base_link">
    <visual>
      <geometry>
        <box size="0.1 0.037 0.171"/>
      </geometry>
      <origin rpy="0 0 0" xyz="0 0.0 0.0995"/>
      <material name="body"/>
    </visual>
    <collision>
      <geometry>
        <box size="0.1 0.037 0.171"/>
      </geometry>
      <origin rpy="0 0 0" xyz="0 0.0 0.0995"/>
    </collision>
    <inertial>
      <mass value="0.514"/>
      <inertia ixx="0.0012568" ixy="0.0" ixz="0.0" iyy="0.001311" iyz="0.0" izz="0.000487"/>
      <origin rpy="0 0 0" xyz="0 0.0 0.057"/>
    </inertial>
  </link>

  <link name="left_wheel">
    <visual>
      <geometry>
        <cylinder length="0.026" radius="0.034"/>
      </geometry>
      <origin rpy="0 1.5707963 0" xyz="0 0 0"/>
      <material name="wheel"/>
    </visual>
    <collision>
      <geometry>
        <cylinder length="0.026" radius="0.034"/>
      </geometry>
      <origin rpy="0 1.5707963 0" xyz="0 0 0"/>
      <contact_coefficients mu="0.8"/>
    </collision>
    <inertial>
      <mass value="0.032"/>
      <inertia ixx="1.3E-05" ixy="0.0" ixz="0.0" iyy="1.3E-05" iyz="0.0" izz="2.3E-05"/>
      <origin rpy="0 0 0" xyz="0 0 0"/>
    </inertial>
  </link>

  <link name="right_wheel">
    <visual>
      <geometry>
        <cylinder length="0.026" radius="0.034"/>
      </geometry>
      <origin rpy="0 1.5707963 0" xyz="0 0 0"/>
      <material name="wheel"/>
    </visual>
    <collision>
      <geometry>
        <cylinder length="0.026" radius="0.034"/>
      </geometry>
      <origin rpy="0 1.5707963 0" xyz="0 0 0"/>
      <contact_coefficients mu="0.8"/>
    </collision>
    <inertial>
      <mass value="0.032"/>
      <inertia ixx="1.3E-05" ixy="0.0" ixz="0.0" iyy="1.3E-05" iyz="0.0" izz="2.3E-05"/>
      <origin rpy="0 0 0" xyz="0 0 0"/>
    </inertial>
  </link>

  <joint name="left_wheel_joint" type="continuous">
    <parent link="base_link"/>
    <child link="left_wheel"/>
    <axis xyz="-1 0 0"/>
    <limit effort="5.0" lower="0.0" upper="0.548" velocity="0.0"/>
    <origin rpy="0 0 0" xyz="-0.074 0.0 0.034"/>
  </joint>

  <joint name="right_wheel_joint" type="continuous">
    <parent link="base_link"/>
    <child link="right_wheel"/>
    <axis xyz="1 0 0"/>
    <limit effort="5.0" lower="0.0" upper="0.548" velocity="0.0"/>
    <origin rpy="0 0 0" xyz="0.074 0.0 0.034"/>
  </joint>

  <link name="imu_link">
    <visual>
      <geometry>
        <box size="0.03 0.03 0.03"/>
      </geometry>
      <origin xyz="0 0 0" rpy="0 0 0"/>
    </visual>
    <collision>
      <geometry>
        <box size="0.05 0.05 0.05"/>
      </geometry>
      <origin xyz="0 0 0" rpy="0 0 0"/>
    </collision>
    <inertial>
      <mass value="0.01"/>
      <origin xyz="0 0 0" rpy="0 0 0"/>
      <inertia ixx="0.0001" iyy="0.0001" izz="0.0001" ixy="0.0" ixz="0.0" iyz="0.0"/>
    </inertial>
  </link>
  <joint name="imu_joint" type="fixed">
    <parent link="base_link"/>
    <child link="imu_link"/>
    <origin xyz="0 0 0.034" rpy="0 0 0"/>
  </joint>

</robot>
